Workbook

Sheet HR Command Center
A1: HR OPERATIONS COMMAND CENTER | S1: ="REPORTING PERIOD: "&TEXT(TODAY(),"MMM-YYYY") -> REPORTING PERIOD: Aug-2026
S2: ="LAST UPDATED: "&TEXT(TODAY(),"DD-MMM-YYYY") -> LAST UPDATED: 31-Aug-2026
A3: People • Attendance • Payroll • Compliance • Workforce Analytics | S3: ="SYSTEM STATUS: ● LIVE | "&COUNTA('Employee Master'!$A$10:$A$109)&" EMPLOYEES LOADED" -> SYSTEM STATUS: ● LIVE | 36 EMPLOYEES LOADED
A4: HOME | B4: PEOPLE | C4: ATTEND. | D4: LEAVE | E4: PAYROLL | F4: DOCS | G4: COMPLY | H4: ANALYTICS | I4: MGMT
B6: WORKFORCE | I6: ATTENDANCE | P6: PAYROLL & COMPLIANCE
B7: TOTAL EMPLOYEES | E7: ACTIVE EMPLOYEES | I7: NEW JOINERS (30D) | L7: EXITS (90D) | P7: ATTENDANCE % (PERIOD) | T7: LATE INSTANCES
B8: =COUNTA('Employee Master'!$A$10:$A$109) -> 36 | E8: =COUNTIF('Employee Master'!$U$10:$U$109,"Active") -> 33 | I8: =COUNTIFS('Employee Master'!$F$10:$F$109,">="&TODAY()-30) -> 3 | L8: =COUNTIFS('Employee Master'!$V$10:$V$109,">="&TODAY()-90) -> 2 | P8: =IFERROR(COUNTIF(Attendance!$E$10:$E$509,"P")/COUNTIF(Attendance!$E$10:$E$509,"<>"),"") -> 0.86928105 | T8: =COUNTIF(Attendance!$K$10:$K$509,"Late") -> 13
B9: ="in roster" -> in roster | E9: ="currently working" -> currently working | I9: ="onboarded this month" -> onboarded this month | L9: ="resigned / terminated" -> resigned / terminated | P9: ="of all logged days" -> of all logged days | T9: ="in the logged period" -> in the logged period
B11: PRESENT (LATEST DAY) | E11: ABSENT (LATEST DAY) | I11: GROSS PAYROLL (LATEST) | M11: NET PAYROLL (LATEST) | Q11: COMPLIANCE SCORE | T11: CRITICAL ALERTS
B12: =COUNTIFS(Attendance!$A$10:$A$509,MAX(Attendance!$A$10:$A$509),Attendance!$E$10:$E$509,"P") -> 33 | E12: =COUNTIFS(Attendance!$A$10:$A$509,MAX(Attendance!$A$10:$A$509),Attendance!$E$10:$E$509,"A") -> 0 | I12: =SUMIFS(Payroll!$F$10:$F$209,Payroll!$A$10:$A$209,Payroll!$A$10) -> 826700 | M12: =SUMIFS(Payroll!$O$10:$O$209,Payroll!$A$10:$A$209,Payroll!$A$10) -> 765330.72 | Q12: =IFERROR(AVERAGE('Document Tracker'!$I$10:$I$109),0) -> 0.54444444 | T12: =COUNTIF('Expiry Tracker'!$F$10:$F$109,"Expired")+COUNTIF('Expiry Tracker'!$F$10:$F$109,"Due in 7 Days") -> 6
B13: ="on latest logged date" -> on latest logged date | E13: ="on latest logged date" -> on latest logged date | I13: ="for "&Payroll!$A$10 -> for Jul-26 | M13: ="after all deductions" -> after all deductions | Q13: ="avg. document completion" -> avg. document completion | T13: ="expired or due within 7 days" -> expired or due within 7 days
B26: WORKFORCE TREND (LAST 6 MONTHS) | P26: ATTENDANCE MIX (PERIOD)
B44: HR INSIGHTS | P44: COMPLIANCE ALERTS
B45: ="Active headcount is "&COUNTIF('Employee Master'!$U$10:$U$109,"Active")&" employees, with "&COUNTIFS('Employee Master'!$F$10:$F$109,">="&TODAY()-30)&" joining in the last 30 days." -> Active headcount is 33 employees, with 3 joining in the last 30 days. | P45: Expired items | U45: =COUNTIF('Expiry Tracker'!$F$10:$F$109,"Expired") -> 6
B46: ="Attendance stood at "&TEXT(IFERROR(COUNTIF(Attendance!$E$10:$E$509,"P")/COUNTIF(Attendance!$E$10:$E$509,"<>"),0),"0.0%")&" across all logged working days, with "&COUNTIF(Attendance!$K$10:$K$509,"Late")&" late instances." -> Attendance stood at 86.9% across all logged working days, with 13 late instances. | P46: Due within 7 days | U46: =COUNTIF('Expiry Tracker'!$F$10:$F$109,"Due in 7 Days") -> 0
B47: ="Latest payroll run totals Rs. "&TEXT(SUMIFS(Payroll!$F$10:$F$209,Payroll!$A$10:$A$209,Payroll!$A$10)/100000,"0.0")&" L gross, with Rs. "&TEXT(SUMIFS(Payroll!$J$10:$J$209,Payroll!$A$10:$A$209,Payroll!$A$10)/1000,"0.0")&"K in overtime." -> Latest payroll run totals Rs. 8.3 L gross, with Rs. 9.3K in overtime. | P47: Due within 30 days | U47: =COUNTIF('Expiry Tracker'!$F$10:$F$109,"Due in 30 Days") -> 5
B48: =IF(COUNTIF('Expiry Tracker'!$F$10:$F$109,"Expired")+COUNTIF('Expiry Tracker'!$F$10:$F$109,"Due in 7 Days")>0,COUNTIF('Expiry Tracker'!$F$10:$F$109,"Expired")+COUNTIF('Expiry Tracker'!$F$10:$F$109,"Due in 7 Days")&" employees need urgent document or licence renewal - see Expiry Tracker.","No urgent compliance actions right now.") -> 6 employees need urgent document or licence renewal - see Expiry Tracker. | P48: Employees with document gaps | U48: =COUNTIFS('Document Tracker'!$I$10:$I$109,"<1",'Document Tracker'!$A$10:$A$109,"<>") -> 41
P50: See full list → Expiry Tracker
B62: Month | C62: New Joiners | D62: Exits | E62: Total Employees | H62: Code | I62: Count
B63: Mar-26 | C63: =COUNTIFS('Employee Master'!$F$10:$F$109,">="&DATE(2026,3,1),'Employee Master'!$F$10:$F$109,"<="&DATE(2026,3,31)) -> 0 | D63: =COUNTIFS('Employee Master'!$V$10:$V$109,">="&DATE(2026,3,1),'Employee Master'!$V$10:$V$109,"<="&DATE(2026,3,31)) -> 0 | E63: =COUNTIFS('Employee Master'!$F$10:$F$109,"<="&DATE(2026,3,31))-COUNTIFS('Employee Master'!$V$10:$V$109,"<="&DATE(2026,3,31),'Employee Master'!$V$10:$V$109,"<>"&"") -> 30 | H63: P | I63: =COUNTIF(Attendance!$E$10:$E$509,"P") -> 266
B64: Apr-26 | C64: =COUNTIFS('Employee Master'!$F$10:$F$109,">="&DATE(2026,4,1),'Employee Master'!$F$10:$F$109,"<="&DATE(2026,4,30)) -> 0 | D64: =COUNTIFS('Employee Master'!$V$10:$V$109,">="&DATE(2026,4,1),'Employee Master'!$V$10:$V$109,"<="&DATE(2026,4,30)) -> 0 | E64: =COUNTIFS('Employee Master'!$F$10:$F$109,"<="&DATE(2026,4,30))-COUNTIFS('Employee Master'!$V$10:$V$109,"<="&DATE(2026,4,30),'Employee Master'!$V$10:$V$109,"<>"&"") -> 30 | H64: A | I64: =COUNTIF(Attendance!$E$10:$E$509,"A") -> 12
B65: May-26 | C65: =COUNTIFS('Employee Master'!$F$10:$F$109,">="&DATE(2026,5,1),'Employee Master'!$F$10:$F$109,"<="&DATE(2026,5,31)) -> 0 | D65: =COUNTIFS('Employee Master'!$V$10:$V$109,">="&DATE(2026,5,1),'Employee Master'!$V$10:$V$109,"<="&DATE(2026,5,31)) -> 0 | E65: =COUNTIFS('Employee Master'!$F$10:$F$109,"<="&DATE(2026,5,31))-COUNTIFS('Employee Master'!$V$10:$V$109,"<="&DATE(2026,5,31),'Employee Master'!$V$10:$V$109,"<>"&"") -> 30 | H65: WO | I65: =COUNTIF(Attendance!$E$10:$E$509,"WO") -> 17
B66: Jun-26 | C66: =COUNTIFS('Employee Master'!$F$10:$F$109,">="&DATE(2026,6,1),'Employee Master'!$F$10:$F$109,"<="&DATE(2026,6,30)) -> 3 | D66: =COUNTIFS('Employee Master'!$V$10:$V$109,">="&DATE(2026,6,1),'Employee Master'!$V$10:$V$109,"<="&DATE(2026,6,30)) -> 0 | E66: =COUNTIFS('Employee Master'!$F$10:$F$109,"<="&DATE(2026,6,30))-COUNTIFS('Employee Master'!$V$10:$V$109,"<="&DATE(2026,6,30),'Employee Master'!$V$10:$V$109,"<>"&"") -> 33 | H66: HD | I66: =COUNTIF(Attendance!$E$10:$E$509,"HD") -> 11
B67: Jul-26 | C67: =COUNTIFS('Employee Master'!$F$10:$F$109,">="&DATE(2026,7,1),'Employee Master'!$F$10:$F$109,"<="&DATE(2026,7,31)) -> 0 | D67: =COUNTIFS('Employee Master'!$V$10:$V$109,">="&DATE(2026,7,1),'Employee Master'!$V$10:$V$109,"<="&DATE(2026,7,31)) -> 1 | E67: =COUNTIFS('Employee Master'!$F$10:$F$109,"<="&DATE(2026,7,31))-COUNTIFS('Employee Master'!$V$10:$V$109,"<="&DATE(2026,7,31),'Employee Master'!$V$10:$V$109,"<>"&"") -> 32 | H67: AL | I67: =COUNTIF(Attendance!$E$10:$E$509,"AL") -> 0
B68: Aug-26 | C68: =COUNTIFS('Employee Master'!$F$10:$F$109,">="&DATE(2026,8,1),'Employee Master'!$F$10:$F$109,"<="&DATE(2026,8,31)) -> 3 | D68: =COUNTIFS('Employee Master'!$V$10:$V$109,">="&DATE(2026,8,1),'Employee Master'!$V$10:$V$109,"<="&DATE(2026,8,31)) -> 1 | E68: =COUNTIFS('Employee Master'!$F$10:$F$109,"<="&DATE(2026,8,31))-COUNTIFS('Employee Master'!$V$10:$V$109,"<="&DATE(2026,8,31),'Employee Master'!$V$10:$V$109,"<>"&"") -> 34 | H68: ML | I68: =COUNTIF(Attendance!$E$10:$E$509,"ML") -> 0
H69: LOP | I69: =COUNTIF(Attendance!$E$10:$E$509,"LOP") -> 0

Sheet Lists
A1: LISTS & SETTINGS
A2: Dropdown values and configurable assumptions - edit here to update every sheet
A3: HOME | B3: PEOPLE | C3: ATTEND. | D3: LEAVE | E3: PAYROLL | F3: DOCS | G3: COMPLY | H3: ANALYTICS | I3: MGMT
A9: Departments | B9: Designations | C9: Employment Type | D9: Status | E9: Attendance | F9: Leave Type | G9: Document Status | H9: Yes/No | I9: Month | K9: Setting | L9: Value
A10: Zone 1 - Water Ops | B10: Admin Officer | C10: Full-Time | D10: Active | E10: P | F10: CL | G10: Available | H10: Yes | I10: Jan-26 | K10: Standard In Time | L10: 0.39583333
A11: Zone 2 - Water Ops | B11: Billing Clerk | C11: Part-Time | D11: Notice Period | E11: A | F11: SL | G11: Pending | H11: No | I11: Feb-26 | K11: Standard Out Time | L11: 0.75
A12: Zone 3 - Water Ops | B12: Data Entry Operator | C12: Contract | D12: Resigned | E12: AL | F12: EL | G12: Missing | I12: Mar-26 | K12: Standard Working Hours/Day | L12: 8
A13: Zone 4 - Water Ops | B13: Electrician | C13: Daily Wage | D13: Terminated | E13: ML | F13: AL | G13: Expired | I13: Apr-26 | K13: PF Rate (Employer, % of Basic) | L13: 0.12
A14: Billing & Revenue | B14: Field Technician | C14: Trainee | E14: LOP | F14: ML | I14: May-26 | K14: ESI Rate (Employer, % of Gross) | L14: 0.0075
A15: Technical & Maintenance | B15: HR Assistant | E15: WO | F15: LOP | I15: Jun-26 | K15: ESI Wage Ceiling (Gross Rs./month) | L15: 21000
A16: HR & Admin | B16: HR Executive | E16: HD | I16: Jul-26
B17: Junior Engineer | I17: Aug-26
B18: Meter Reader | I18: Sep-26
B19: Office Supervisor | I19: Oct-26
B20: Plumber Technician | I20: Nov-26
B21: Revenue Inspector | I21: Dec-26
B22: Store Keeper
B23: Valve Operator
B24: Zone Supervisor

Sheet Employee Master
A1: EMPLOYEE MASTER
A2: Core HR database - single source of truth for every lookup in this workbook
A3: HOME | B3: PEOPLE | C3: ATTEND. | D3: LEAVE | E3: PAYROLL | F3: DOCS | G3: COMPLY | H3: ANALYTICS | I3: MGMT
B5: ACTIVE EMPLOYEES | F5: NEW JOINERS (30D) | J5: EXITS (LAST 90D) | N5: AVG SERVICE (YRS)
B6: =COUNTIF($U$10:$U$109,"Active") -> 33 | F6: =COUNTIFS($F$10:$F$109,">="&TODAY()-30,$F$10:$F$109,"<="&TODAY()) -> 3 | J6: =COUNTIFS($V$10:$V$109,">="&TODAY()-90,$V$10:$V$109,"<>"&"") -> 2 | N6: =IFERROR(ROUND(AVERAGEIF($U$10:$U$109,"Active",$G$10:$G$109),1),0) -> 3
B7: ="of "&COUNTA($A$10:$A$109)&" in roster" -> of 36 in roster | F7: ="joined in the last 30 days" -> joined in the last 30 days | J7: ="resigned / terminated" -> resigned / terminated | N7: ="across active employees" -> across active employees
A9: Employee ID | B9: Employee Name | C9: Gender | D9: DOB | E9: Age | F9: DOJ | G9: Service (Yrs) | H9: Department | I9: Designation | J9: Employment Type | K9: Phone | L9: Email | M9: PAN | N9: Aadhaar | O9: Bank A/C | P9: IFSC | Q9: Basic Salary | R9: Gross Salary | S9: PF Applicable | T9: ESI Applicable | U9: Status | V9: Exit Date
A10: XXX-01 | B10: Murugesan P | C10: Male | D10: 35846 | E10: =IFERROR(DATEDIF(D10,TODAY(),"Y"),"") -> 28 | F10: 46239 | G10: =IFERROR(ROUND(YEARFRAC(F10,TODAY()),1),"") -> 0.1 | H10: Human Resources | I10: HR Manager | J10: Full-Time | Q10: 15656 | R10: 21150 | S10: Yes | T10: No | U10: Active
A11: XXX-02 | B11: Vijay K | C11: Male | D11: 36116 | E11: =IFERROR(DATEDIF(D11,TODAY(),"Y"),"") -> 27 | F11: 46244 | G11: =IFERROR(ROUND(YEARFRAC(F11,TODAY()),1),"") -> 0.1 | H11: Finance & Accounts | I11: HR Assistant | J11: Full-Time | Q11: 23632 | R11: 31900 | S11: Yes | T11: No | U11: Active
A12: XXX-03 | B12: Murugesan P | C12: Male | D12: 37016 | E12: =IFERROR(DATEDIF(D12,TODAY(),"Y"),"") -> 25 | F12: 46256 | G12: =IFERROR(ROUND(YEARFRAC(F12,TODAY()),1),"") -> 0 | H12: Administration | I12: Payroll Executive | J12: Full-Time | Q12: 12590 | R12: 17000 | S12: Yes | T12: Yes | U12: Active
A13: XXX-04 | B13: Murugesan S | C13: Male | D13: 34155 | E13: =IFERROR(DATEDIF(D13,TODAY(),"Y"),"") -> 33 | F13: 46197 | G13: =IFERROR(ROUND(YEARFRAC(F13,TODAY()),1),"") -> 0.2 | H13: Operations | I13: Admin Executive | J13: Full-Time | Q13: 13039 | R13: 17600 | S13: Yes | T13: Yes | U13: Active
A14: XXX-05 | B14: Murugesan | C14: Male | D14: 33222 | E14: =IFERROR(DATEDIF(D14,TODAY(),"Y"),"") -> 35 | F14: 46191 | G14: =IFERROR(ROUND(YEARFRAC(F14,TODAY()),1),"") -> 0.2 | H14: Sales & Marketing | I14: Operations Manager | J14: Full-Time | Q14: 14073 | R14: 19000 | S14: Yes | T14: Yes | U14: Active
A15: XXX-06 | B15: Elango K | C15: Male | D15: 33850 | E15: =IFERROR(DATEDIF(D15,TODAY(),"Y"),"") -> 33 | F15: 46185 | G15: =IFERROR(ROUND(YEARFRAC(F15,TODAY()),1),"") -> 0.2 | H15: IT & Systems | I15: Operations Executive | J15: Contract | Q15: 26705 | R15: 36050 | S15: Yes | T15: No | U15: Active
A16: XXX-07 | B16: Murugan | C16: Male | D16: 31339 | E16: =IFERROR(DATEDIF(D16,TODAY(),"Y"),"") -> 40 | F16: 45871 | G16: =IFERROR(ROUND(YEARFRAC(F16,TODAY()),1),"") -> 1.1 | H16: Procurement | I16: HR Manager | J16: Full-Time | Q16: 14925 | R16: 20150 | S16: Yes | T16: Yes | U16: Active
A17: XXX-08 | B17: Bala Murugan | C17: Male | D17: 36479 | E17: =IFERROR(DATEDIF(D17,TODAY(),"Y"),"") -> 26 | F17: 43823 | G17: =IFERROR(ROUND(YEARFRAC(F17,TODAY()),1),"") -> 6.7 | H17: Quality Control | I17: HR Assistant | J17: Full-Time | Q17: 21570 | R17: 29100 | S17: Yes | T17: No | U17: Active
A18: XXX-09 | B18: Murugesan V | C18: Male | D18: 36717 | E18: =IFERROR(DATEDIF(D18,TODAY(),"Y"),"") -> 26 | F18: 45065 | G18: =IFERROR(ROUND(YEARFRAC(F18,TODAY()),1),"") -> 3.3 | H18: Maintenance | I18: Payroll Executive | J18: Full-Time | Q18: 19532 | R18: 26350 | S18: Yes | T18: No | U18: Active
A19: XXX-10 | B19: Elango P | C19: Male | D19: 30178 | E19: =IFERROR(DATEDIF(D19,TODAY(),"Y"),"") -> 44 | F19: 44279 | G19: =IFERROR(ROUND(YEARFRAC(F19,TODAY()),1),"") -> 5.4 | H19: Customer Support | I19: Admin Executive | J19: Contract | Q19: 19959 | R19: 26950 | S19: Yes | T19: No | U19: Active
A20: XXX-11 | B20: Senthil Kumar K | C20: Male | D20: 28893 | E20: =IFERROR(DATEDIF(D20,TODAY(),"Y"),"") -> 47 | F20: 44137 | G20: =IFERROR(ROUND(YEARFRAC(F20,TODAY()),1),"") -> 5.8 | H20: Human Resources | I20: Operations Manager | J20: Full-Time | Q20: 15179 | R20: 20500 | S20: Yes | T20: Yes | U20: Active
A21: XXX-12 | B21: Saravanan P | C21: Male | D21: 29840 | E21: =IFERROR(DATEDIF(D21,TODAY(),"Y"),"") -> 44 | F21: 44612 | G21: =IFERROR(ROUND(YEARFRAC(F21,TODAY()),1),"") -> 4.5 | H21: Finance & Accounts | I21: Operations Executive | J21: Daily Wage | Q21: 12736 | R21: 17200 | S21: No | T21: Yes | U21: Active
... A42: XXX-33 | B42: Selvam K | C42: Male | D42: 26039 | E42: =IFERROR(DATEDIF(D42,TODAY(),"Y"),"") -> 55 | F42: 43879 | G42: =IFERROR(ROUND(YEARFRAC(F42,TODAY()),1),"") -> 6.5 | H42: Administration | I42: Payroll Executive | J42: Daily Wage | Q42: 20659 | R42: 27900 | S42: No | T42: No | U42: Active
A43: XXX-34 | B43: Revathi V | C43: Female | D43: 30883 | E43: =IFERROR(DATEDIF(D43,TODAY(),"Y"),"") -> 42 | F43: 43421 | G43: =IFERROR(ROUND(YEARFRAC(F43,TODAY()),1),"") -> 7.8 | H43: Operations | I43: Admin Executive | J43: Contract | Q43: 12099 | R43: 16350 | S43: Yes | T43: Yes | U43: Terminated | V43: 46224
A44: XXX-35 | B44: Naveen M | C44: Male | D44: 34808 | E44: =IFERROR(DATEDIF(D44,TODAY(),"Y"),"") -> 31 | F44: 45608 | G44: =IFERROR(ROUND(YEARFRAC(F44,TODAY()),1),"") -> 1.8 | H44: Sales & Marketing | I44: Operations Manager | J44: Daily Wage | Q44: 13298 | R44: 17950 | S44: No | T44: Yes | U44: Notice Period
A45: XXX-36 | B45: Kavitha K | C45: Female | D45: 34211 | E45: =IFERROR(DATEDIF(D45,TODAY(),"Y"),"") -> 33 | F45: 44403 | G45: =IFERROR(ROUND(YEARFRAC(F45,TODAY()),1),"") -> 5.1 | H45: IT & Systems | I45: HR Manager | J45: Daily Wage | Q45: 22308 | R45: 30100 | S45: No | T45: No | U45: Resigned | V45: 46248
E46: =IFERROR(DATEDIF(D46,TODAY(),"Y"),"") -> 126 | G46: =IFERROR(ROUND(YEARFRAC(F46,TODAY()),1),"") -> 126.7
E47: =IFERROR(DATEDIF(D47,TODAY(),"Y"),"") -> 126 | G47: =IFERROR(ROUND(YEARFRAC(F47,TODAY()),1),"") -> 126.7
E48: =IFERROR(DATEDIF(D48,TODAY(),"Y"),"") -> 126 | G48: =IFERROR(ROUND(YEARFRAC(F48,TODAY()),1),"") -> 126.7
E49: =IFERROR(DATEDIF(D49,TODAY(),"Y"),"") -> 126 | G49: =IFERROR(ROUND(YEARFRAC(F49,TODAY()),1),"") -> 126.7
E50: =IFERROR(DATEDIF(D50,TODAY(),"Y"),"") -> 126 | G50: =IFERROR(ROUND(YEARFRAC(F50,TODAY()),1),"") -> 126.7
E51: =IFERROR(DATEDIF(D51,TODAY(),"Y"),"") -> 126 | G51: =IFERROR(ROUND(YEARFRAC(F51,TODAY()),1),"") -> 126.7
E52: =IFERROR(DATEDIF(D52,TODAY(),"Y"),"") -> 126 | G52: =IFERROR(ROUND(YEARFRAC(F52,TODAY()),1),"") -> 126.7
E53: =IFERROR(DATEDIF(D53,TODAY(),"Y"),"") -> 126 | G53: =IFERROR(ROUND(YEARFRAC(F53,TODAY()),1),"") -> 126.7
E54: =IFERROR(DATEDIF(D54,TODAY(),"Y"),"") -> 126 | G54: =IFERROR(ROUND(YEARFRAC(F54,TODAY()),1),"") -> 126.7
E55: =IFERROR(DATEDIF(D55,TODAY(),"Y"),"") -> 126 | G55: =IFERROR(ROUND(YEARFRAC(F55,TODAY()),1),"") -> 126.7
E56: =IFERROR(DATEDIF(D56,TODAY(),"Y"),"") -> 126 | G56: =IFERROR(ROUND(YEARFRAC(F56,TODAY()),1),"") -> 126.7
E57: =IFERROR(DATEDIF(D57,TODAY(),"Y"),"") -> 126 | G57: =IFERROR(ROUND(YEARFRAC(F57,TODAY()),1),"") -> 126.7
... E109: =IFERROR(DATEDIF(D109,TODAY(),"Y"),"") -> 126 | G109: =IFERROR(ROUND(YEARFRAC(F109,TODAY()),1),"") -> 126.7

Sheet Attendance
A1: ATTENDANCE TRACKER
A2: Daily attendance log with automatic lookups, working hours and lateness flags
A3: HOME | B3: PEOPLE | C3: ATTEND. | D3: LEAVE | E3: PAYROLL | F3: DOCS | G3: COMPLY | H3: ANALYTICS | I3: MGMT
B5: ATTENDANCE % (PERIOD) | E5: PRESENT (LATEST DAY) | I5: ABSENT (LATEST DAY) | L5: LATE (LATEST DAY)
B6: =IFERROR(COUNTIF($E$10:$E$509,"P")/COUNTIFS($E$10:$E$509,"<>"),"") -> 0.86928105 | E6: =COUNTIFS($A$10:$A$509,MAX($A$10:$A$509),$E$10:$E$509,"P") -> 33 | I6: =COUNTIFS($A$10:$A$509,MAX($A$10:$A$509),$E$10:$E$509,"A") -> 0 | L6: =COUNTIFS($A$10:$A$509,MAX($A$10:$A$509),$K$10:$K$509,"Late") -> 0
B7: ="of all logged days" -> of all logged days | E7: ="on "&TEXT(MAX($A$10:$A$509),"dd-mmm") -> on 26-Aug | I7: ="on "&TEXT(MAX($A$10:$A$509),"dd-mmm") -> on 26-Aug | L7: ="in vs. standard shift time" -> in vs. standard shift time
A9: Date | B9: Employee ID | C9: Employee Name | D9: Department | E9: Attendance Code | F9: In Time | G9: Out Time | H9: OT Hours | I9: Remarks | J9: Working Hours | K9: Late | L9: Early Exit | M9: Status
A10: 46251 | B10: XXX-01 | C10: =IFERROR(INDEX('Employee Master'!$B$10:$B$109,MATCH(B10,'Employee Master'!$A$10:$A$109,0)),"") -> Murugesan P | D10: =IFERROR(INDEX('Employee Master'!$H$10:$H$109,MATCH(B10,'Employee Master'!$A$10:$A$109,0)),"") -> Human Resources | E10: P | F10: 0.38541667 | G10: 0.75694444 | H10: 2 | J10: =IF(AND(F10<>"",G10<>""),ROUND((G10-F10)*24,2),"") -> 8.92 | K10: =IF(F10<>"",IF(F10>Lists!$L$10,"Late","On Time"),"") -> On Time | L10: =IF(G10<>"",IF(G10<Lists!$L$11,"Early","On Time"),"") -> On Time | M10: =IF(E10="","",E10&IF(K10="Late"," +Late","")&IF(L10="Early"," +Early Exit","")) -> P
A11: 46251 | B11: XXX-02 | C11: =IFERROR(INDEX('Employee Master'!$B$10:$B$109,MATCH(B11,'Employee Master'!$A$10:$A$109,0)),"") -> Vijay K | D11: =IFERROR(INDEX('Employee Master'!$H$10:$H$109,MATCH(B11,'Employee Master'!$A$10:$A$109,0)),"") -> Finance & Accounts | E11: A | H11: 0 | J11: =IF(AND(F11<>"",G11<>""),ROUND((G11-F11)*24,2),"") | K11: =IF(F11<>"",IF(F11>Lists!$L$10,"Late","On Time"),"") | L11: =IF(G11<>"",IF(G11<Lists!$L$11,"Early","On Time"),"") | M11: =IF(E11="","",E11&IF(K11="Late"," +Late","")&IF(L11="Early"," +Early Exit","")) -> A
A12: 46251 | B12: XXX-03 | C12: =IFERROR(INDEX('Employee Master'!$B$10:$B$109,MATCH(B12,'Employee Master'!$A$10:$A$109,0)),"") -> Murugesan P | D12: =IFERROR(INDEX('Employee Master'!$H$10:$H$109,MATCH(B12,'Employee Master'!$A$10:$A$109,0)),"") -> Administration | E12: P | F12: 0.37847222 | G12: 0.76388889 | H12: 0 | J12: =IF(AND(F12<>"",G12<>""),ROUND((G12-F12)*24,2),"") -> 9.25 | K12: =IF(F12<>"",IF(F12>Lists!$L$10,"Late","On Time"),"") -> On Time | L12: =IF(G12<>"",IF(G12<Lists!$L$11,"Early","On Time"),"") -> On Time | M12: =IF(E12="","",E12&IF(K12="Late"," +Late","")&IF(L12="Early"," +Early Exit","")) -> P
A13: 46251 | B13: XXX-04 | C13: =IFERROR(INDEX('Employee Master'!$B$10:$B$109,MATCH(B13,'Employee Master'!$A$10:$A$109,0)),"") -> Murugesan S | D13: =IFERROR(INDEX('Employee Master'!$H$10:$H$109,MATCH(B13,'Employee Master'!$A$10:$A$109,0)),"") -> Operations | E13: P | F13: 0.39027778 | G13: 0.75 | H13: 1.5 | J13: =IF(AND(F13<>"",G13<>""),ROUND((G13-F13)*24,2),"") -> 8.63 | K13: =IF(F13<>"",IF(F13>Lists!$L$10,"Late","On Time"),"") -> On Time | L13: =IF(G13<>"",IF(G13<Lists!$L$11,"Early","On Time"),"") -> On Time | M13: =IF(E13="","",E13&IF(K13="Late"," +Late","")&IF(L13="Early"," +Early Exit","")) -> P
A14: 46251 | B14: XXX-05 | C14: =IFERROR(INDEX('Employee Master'!$B$10:$B$109,MATCH(B14,'Employee Master'!$A$10:$A$109,0)),"") -> Murugesan | D14: =IFERROR(INDEX('Employee Master'!$H$10:$H$109,MATCH(B14,'Employee Master'!$A$10:$A$109,0)),"") -> Sales & Marketing | E14: P | F14: 0.37847222 | G14: 0.75 | H14: 0 | J14: =IF(AND(F14<>"",G14<>""),ROUND((G14-F14)*24,2),"") -> 8.92 | K14: =IF(F14<>"",IF(F14>Lists!$L$10,"Late","On Time"),"") -> On Time | L14: =IF(G14<>"",IF(G14<Lists!$L$11,"Early","On Time"),"") -> On Time | M14: =IF(E14="","",E14&IF(K14="Late"," +Late","")&IF(L14="Early"," +Early Exit","")) -> P
A15: 46251 | B15: XXX-06 | C15: =IFERROR(INDEX('Employee Master'!$B$10:$B$109,MATCH(B15,'Employee Master'!$A$10:$A$109,0)),"") -> Elango K | D15: =IFERROR(INDEX('Employee Master'!$H$10:$H$109,MATCH(B15,'Employee Master'!$A$10:$A$109,0)),"") -> IT & Systems | E15: A | H15: 0 | J15: =IF(AND(F15<>"",G15<>""),ROUND((G15-F15)*24,2),"") | K15: =IF(F15<>"",IF(F15>Lists!$L$10,"Late","On Time"),"") | L15: =IF(G15<>"",IF(G15<Lists!$L$11,"Early","On Time"),"") | M15: =IF(E15="","",E15&IF(K15="Late"," +Late","")&IF(L15="Early"," +Early Exit","")) -> A
A16: 46251 | B16: XXX-07 | C16: =IFERROR(INDEX('Employee Master'!$B$10:$B$109,MATCH(B16,'Employee Master'!$A$10:$A$109,0)),"") -> Murugan | D16: =IFERROR(INDEX('Employee Master'!$H$10:$H$109,MATCH(B16,'Employee Master'!$A$10:$A$109,0)),"") -> Procurement | E16: P | F16: 0.3875 | G16: 0.75694444 | H16: 0 | J16: =IF(AND(F16<>"",G16<>""),ROUND((G16-F16)*24,2),"") -> 8.87 | K16: =IF(F16<>"",IF(F16>Lists!$L$10,"Late","On Time"),"") -> On Time | L16: =IF(G16<>"",IF(G16<Lists!$L$11,"Early","On Time"),"") -> On Time | M16: =IF(E16="","",E16&IF(K16="Late"," +Late","")&IF(L16="Early"," +Early Exit","")) -> P
A17: 46251 | B17: XXX-08 | C17: =IFERROR(INDEX('Employee Master'!$B$10:$B$109,MATCH(B17,'Employee Master'!$A$10:$A$109,0)),"") -> Bala Murugan | D17: =IFERROR(INDEX('Employee Master'!$H$10:$H$109,MATCH(B17,'Employee Master'!$A$10:$A$109,0)),"") -> Quality Control | E17: P | F17: 0.39027778 | G17: 0.77430556 | H17: 0 | J17: =IF(AND(F17<>"",G17<>""),ROUND((G17-F17)*24,2),"") -> 9.22 | K17: =IF(F17<>"",IF(F17>Lists!$L$10,"Late","On Time"),"") -> On Time | L17: =IF(G17<>"",IF(G17<Lists!$L$11,"Early","On Time"),"") -> On Time | M17: =IF(E17="","",E17&IF(K17="Late"," +Late","")&IF(L17="Early"," +Early Exit","")) -> P
A18: 46251 | B18: XXX-09 | C18: =IFERROR(INDEX('Employee Master'!$B$10:$B$109,MATCH(B18,'Employee Master'!$A$10:$A$109,0)),"") -> Murugesan V | D18: =IFERROR(INDEX('Employee Master'!$H$10:$H$109,MATCH(B18,'Employee Master'!$A$10:$A$109,0)),"") -> Maintenance | E18: P | F18: 0.38541667 | G18: 0.75 | H18: 0 | J18: =IF(AND(F18<>"",G18<>""),ROUND((G18-F18)*24,2),"") -> 8.75 | K18: =IF(F18<>"",IF(F18>Lists!$L$10,"Late","On Time"),"") -> On Time | L18: =IF(G18<>"",IF(G18<Lists!$L$11,"Early","On Time"),"") -> On Time | M18: =IF(E18="","",E18&IF(K18="Late"," +Late","")&IF(L18="Early"," +Early Exit","")) -> P
A19: 46251 | B19: XXX-10 | C19: =IFERROR(INDEX('Employee Master'!$B$10:$B$109,MATCH(B19,'Employee Master'!$A$10:$A$109,0)),"") -> Elango P | D19: =IFERROR(INDEX('Employee Master'!$H$10:$H$109,MATCH(B19,'Employee Master'!$A$10:$A$109,0)),"") -> Customer Support | E19: P | F19: 0.37847222 | G19: 0.75694444 | H19: 0 | J19: =IF(AND(F19<>"",G19<>""),ROUND((G19-F19)*24,2),"") -> 9.08 | K19: =IF(F19<>"",IF(F19>Lists!$L$10,"Late","On Time"),"") -> On Time | L19: =IF(G19<>"",IF(G19<Lists!$L$11,"Early","On Time"),"") -> On Time | M19: =IF(E19="","",E19&IF(K19="Late"," +Late","")&IF(L19="Early"," +Early Exit","")) -> P
A20: 46251 | B20: XXX-11 | C20: =IFERROR(INDEX('Employee Master'!$B$10:$B$109,MATCH(B20,'Employee Master'!$A$10:$A$109,0)),"") -> Senthil Kumar K | D20: =IFERROR(INDEX('Employee Master'!$H$10:$H$109,MATCH(B20,'Employee Master'!$A$10:$A$109,0)),"") -> Human Resources | E20: P | F20: 0.38541667 | G20: 0.75 | H20: 0 | J20: =IF(AND(F20<>"",G20<>""),ROUND((G20-F20)*24,2),"") -> 8.75 | K20: =IF(F20<>"",IF(F20>Lists!$L$10,"Late","On Time"),"") -> On Time | L20: =IF(G20<>"",IF(G20<Lists!$L$11,"Early","On Time"),"") -> On Time | M20: =IF(E20="","",E20&IF(K20="Late"," +Late","")&IF(L20="Early"," +Early Exit","")) -> P
A21: 46251 | B21: XXX-12 | C21: =IFERROR(INDEX('Employee Master'!$B$10:$B$109,MATCH(B21,'Employee Master'!$A$10:$A$109,0)),"") -> Saravanan P | D21: =IFERROR(INDEX('Employee Master'!$H$10:$H$109,MATCH(B21,'Employee Master'!$A$10:$A$109,0)),"") -> Finance & Accounts | E21: P | F21: 0.38541667 | G21: 0.75 | H21: 0 | J21: =IF(AND(F21<>"",G21<>""),ROUND((G21-F21)*24,2),"") -> 8.75 | K21: =IF(F21<>"",IF(F21>Lists!$L$10,"Late","On Time"),"") -> On Time | L21: =IF(G21<>"",IF(G21<Lists!$L$11,"Early","On Time"),"") -> On Time | M21: =IF(E21="","",E21&IF(K21="Late"," +Late","")&IF(L21="Early"," +Early Exit","")) -> P
A22: 46251 | B22: XXX-13 | C22: =IFERROR(INDEX('Employee Master'!$B$10:$B$109,MATCH(B22,'Employee Master'!$A$10:$A$109,0)),"") -> Karthik V | D22: =IFERROR(INDEX('Employee Master'!$H$10:$H$109,MATCH(B22,'Employee Master'!$A$10:$A$109,0)),"") -> Administration | E22: P | F22: 0.39027778 | G22: 0.76388889 | H22: 0 | J22: =IF(AND(F22<>"",G22<>""),ROUND((G22-F22)*24,2),"") -> 8.97 | K22: =IF(F22<>"",IF(F22>Lists!$L$10,"Late","On Time"),"") -> On Time | L22: =IF(G22<>"",IF(G22<Lists!$L$11,"Early","On Time"),"") -> On Time | M22: =IF(E22="","",E22&IF(K22="Late"," +Late","")&IF(L22="Early"," +Early Exit","")) -> P
A23: 46251 | B23: XXX-14 | C23: =IFERROR(INDEX('Employee Master'!$B$10:$B$109,MATCH(B23,'Employee Master'!$A$10:$A$109,0)),"") -> Senthil Kumar | D23: =IFERROR(INDEX('Employee Master'!$H$10:$H$109,MATCH(B23,'Employee Master'!$A$10:$A$109,0)),"") -> Operations | E23: P | F23: 0.38194444 | G23: 0.75 | H23: 0 | J23: =IF(AND(F23<>"",G23<>""),ROUND((G23-F23)*24,2),"") -> 8.83 | K23: =IF(F23<>"",IF(F23>Lists!$L$10,"Late","On Time"),"") -> On Time | L23: =IF(G23<>"",IF(G23<Lists!$L$11,"Early","On Time"),"") -> On Time | M23: =IF(E23="","",E23&IF(K23="Late"," +Late","")&IF(L23="Early"," +Early Exit","")) -> P
A24: 46251 | B24: XXX-15 | C24: =IFERROR(INDEX('Employee Master'!$B$10:$B$109,MATCH(B24,'Employee Master'!$A$10:$A$109,0)),"") -> Gopinath P | D24: =IFERROR(INDEX('Employee Master'!$H$10:$H$109,MATCH(B24,'Employee Master'!$A$10:$A$109,0)),"") -> Sales & Marketing | E24: P | F24: 0.37847222 | G24: 0.75347222 | H24: 0 | J24: =IF(AND(F24<>"",G24<>""),ROUND((G24-F24)*24,2),"") -> 9 | K24: =IF(F24<>"",IF(F24>Lists!$L$10,"Late","On Time"),"") -> On Time | L24: =IF(G24<>"",IF(G24<Lists!$L$11,"Early","On Time"),"") -> On Time | M24: =IF(E24="","",E24&IF(K24="Late"," +Late","")&IF(L24="Early"," +Early Exit","")) -> P
A25: 46251 | B25: XXX-16 | C25: =IFERROR(INDEX('Employee Master'!$B$10:$B$109,MATCH(B25,'Employee Master'!$A$10:$A$109,0)),"") -> Muthu Raj | D25: =IFERROR(INDEX('Employee Master'!$H$10:$H$109,MATCH(B25,'Employee Master'!$A$10:$A$109,0)),"") -> IT & Systems | E25: P | F25: 0.38541667 | G25: 0.75694444 | H25: 0 | J25: =IF(AND(F25<>"",G25<>""),ROUND((G25-F25)*24,2),"") -> 8.92 | K25: =IF(F25<>"",IF(F25>Lists!$L$10,"Late","On Time"),"") -> On Time | L25: =IF(G25<>"",IF(G25<Lists!$L$11,"Early","On Time"),"") -> On Time | M25: =IF(E25="","",E25&IF(K25="Late"," +Late","")&IF(L25="Early"," +Early Exit","")) -> P
A26: 46251 | B26: XXX-17 | C26: =IFERROR(INDEX('Employee Master'!$B$10:$B$109,MATCH(B26,'Employee Master'!$A$10:$A$109,0)),"") -> Senthil Kumar S | D26: =IFERROR(INDEX('Employee Master'!$H$10:$H$109,MATCH(B26,'Employee Master'!$A$10:$A$109,0)),"") -> Procurement | E26: P | F26: 0.3875 | G26: 0.77430556 | H26: 0 | J26: =IF(AND(F26<>"",G26<>""),ROUND((G26-F26)*24,2),"") -> 9.28 | K26: =IF(F26<>"",IF(F26>Lists!$L$10,"Late","On Time"),"") -> On Time | L26: =IF(G26<>"",IF(G26<Lists!$L$11,"Early","On Time"),"") -> On Time | M26: =IF(E26="","",E26&IF(K26="Late"," +Late","")&IF(L26="Early"," +Early Exit","")) -> P
A27: 46251 | B27: XXX-18 | C27: =IFERROR(INDEX('Employee Master'!$B$10:$B$109,MATCH(B27,'Employee Master'!$A$10:$A$109,0)),"") -> Sowmya V | D27: =IFERROR(INDEX('Employee Master'!$H$10:$H$109,MATCH(B27,'Employee Master'!$A$10:$A$109,0)),"") -> Quality Control | E27: P | F27: 0.37847222 | G27: 0.75694444 | H27: 1 | J27: =IF(AND(F27<>"",G27<>""),ROUND((G27-F27)*24,2),"") -> 9.08 | K27: =IF(F27<>"",IF(F27>Lists!$L$10,"Late","On Time"),"") -> On Time | L27: =IF(G27<>"",IF(G27<Lists!$L$11,"Early","On Time"),"") -> On Time | M27: =IF(E27="","",E27&IF(K27="Late"," +Late","")&IF(L27="Early"," +Early Exit","")) -> P
... A40: 46251 | B40: XXX-31 | C40: =IFERROR(INDEX('Employee Master'!$B$10:$B$109,MATCH(B40,'Employee Master'!$A$10:$A$109,0)),"") -> Suresh K | D40: =IFERROR(INDEX('Employee Master'!$H$10:$H$109,MATCH(B40,'Employee Master'!$A$10:$A$109,0)),"") -> Human Resources | E40: P | F40: 0.38541667 | G40: 0.75347222 | H40: 0 | J40: =IF(AND(F40<>"",G40<>""),ROUND((G40-F40)*24,2),"") -> 8.83 | K40: =IF(F40<>"",IF(F40>Lists!$L$10,"Late","On Time"),"") -> On Time | L40: =IF(G40<>"",IF(G40<Lists!$L$11,"Early","On Time"),"") -> On Time | M40: =IF(E40="","",E40&IF(K40="Late"," +Late","")&IF(L40="Early"," +Early Exit","")) -> P
A41: 46251 | B41: XXX-32 | C41: =IFERROR(INDEX('Employee Master'!$B$10:$B$109,MATCH(B41,'Employee Master'!$A$10:$A$109,0)),"") -> Sathish M | D41: =IFERROR(INDEX('Employee Master'!$H$10:$H$109,MATCH(B41,'Employee Master'!$A$10:$A$109,0)),"") -> Finance & Accounts | E41: A | H41: 0 | J41: =IF(AND(F41<>"",G41<>""),ROUND((G41-F41)*24,2),"") | K41: =IF(F41<>"",IF(F41>Lists!$L$10,"Late","On Time"),"") | L41: =IF(G41<>"",IF(G41<Lists!$L$11,"Early","On Time"),"") | M41: =IF(E41="","",E41&IF(K41="Late"," +Late","")&IF(L41="Early"," +Early Exit","")) -> A
A42: 46251 | B42: XXX-33 | C42: =IFERROR(INDEX('Employee Master'!$B$10:$B$109,MATCH(B42,'Employee Master'!$A$10:$A$109,0)),"") -> Selvam K | D42: =IFERROR(INDEX('Employee Master'!$H$10:$H$109,MATCH(B42,'Employee Master'!$A$10:$A$109,0)),"") -> Administration | E42: P | F42: 0.39027778 | G42: 0.75347222 | H42: 0 | J42: =IF(AND(F42<>"",G42<>""),ROUND((G42-F42)*24,2),"") -> 8.72 | K42: =IF(F42<>"",IF(F42>Lists!$L$10,"Late","On Time"),"") -> On Time | L42: =IF(G42<>"",IF(G42<Lists!$L$11,"Early","On Time"),"") -> On Time | M42: =IF(E42="","",E42&IF(K42="Late"," +Late","")&IF(L42="Early"," +Early Exit","")) -> P
A43: 46251 | B43: XXX-34 | C43: =IFERROR(INDEX('Employee Master'!$B$10:$B$109,MATCH(B43,'Employee Master'!$A$10:$A$109,0)),"") -> Revathi V | D43: =IFERROR(INDEX('Employee Master'!$H$10:$H$109,MATCH(B43,'Employee Master'!$A$10:$A$109,0)),"") -> Operations | E43: P | F43: 0.37847222 | G43: 0.75694444 | H43: 0 | J43: =IF(AND(F43<>"",G43<>""),ROUND((G43-F43)*24,2),"") -> 9.08 | K43: =IF(F43<>"",IF(F43>Lists!$L$10,"Late","On Time"),"") -> On Time | L43: =IF(G43<>"",IF(G43<Lists!$L$11,"Early","On Time"),"") -> On Time | M43: =IF(E43="","",E43&IF(K43="Late"," +Late","")&IF(L43="Early"," +Early Exit","")) -> P
A44: 46252 | B44: XXX-35 | C44: =IFERROR(INDEX('Employee Master'!$B$10:$B$109,MATCH(B44,'Employee Master'!$A$10:$A$109,0)),"") -> Naveen M | D44: =IFERROR(INDEX('Employee Master'!$H$10:$H$109,MATCH(B44,'Employee Master'!$A$10:$A$109,0)),"") -> Sales & Marketing | E44: P | F44: 0.42013889 | G44: 0.42013889 | H44: 0 | J44: =IF(AND(F44<>"",G44<>""),ROUND((G44-F44)*24,2),"") -> 0 | K44: =IF(F44<>"",IF(F44>Lists!$L$10,"Late","On Time"),"") -> Late | L44: =IF(G44<>"",IF(G44<Lists!$L$11,"Early","On Time"),"") -> Early | M44: =IF(E44="","",E44&IF(K44="Late"," +Late","")&IF(L44="Early"," +Early Exit","")) -> P +Late +Early Exit
A45: 46252 | B45: XXX-36 | C45: =IFERROR(INDEX('Employee Master'!$B$10:$B$109,MATCH(B45,'Employee Master'!$A$10:$A$109,0)),"") -> Kavitha K | D45: =IFERROR(INDEX('Employee Master'!$H$10:$H$109,MATCH(B45,'Employee Master'!$A$10:$A$109,0)),"") -> IT & Systems | E45: P | F45: 0.37847222 | G45: 0.77430556 | H45: 0 | J45: =IF(AND(F45<>"",G45<>""),ROUND((G45-F45)*24,2),"") -> 9.5 | K45: =IF(F45<>"",IF(F45>Lists!$L$10,"Late","On Time"),"") -> On Time | L45: =IF(G45<>"",IF(G45<Lists!$L$11,"Early","On Time"),"") -> On Time | M45: =IF(E45="","",E45&IF(K45="Late"," +Late","")&IF(L45="Early"," +Early Exit","")) -> P
A46: 46252 | B46: XXX-37 | C46: =IFERROR(INDEX('Employee Master'!$B$10:$B$109,MATCH(B46,'Employee Master'!$A$10:$A$109,0)),"") | D46: =IFERROR(INDEX('Employee Master'!$H$10:$H$109,MATCH(B46,'Employee Master'!$A$10:$A$109,0)),"") | E46: P | F46: 0.38194444 | G46: 0.77430556 | H46: 0 | J46: =IF(AND(F46<>"",G46<>""),ROUND((G46-F46)*24,2),"") -> 9.42 | K46: =IF(F46<>"",IF(F46>Lists!$L$10,"Late","On Time"),"") -> On Time | L46: =IF(G46<>"",IF(G46<Lists!$L$11,"Early","On Time"),"") -> On Time | M46: =IF(E46="","",E46&IF(K46="Late"," +Late","")&IF(L46="Early"," +Early Exit","")) -> P
A47: 46252 | B47: XXX-38 | C47: =IFERROR(INDEX('Employee Master'!$B$10:$B$109,MATCH(B47,'Employee Master'!$A$10:$A$109,0)),"") | D47: =IFERROR(INDEX('Employee Master'!$H$10:$H$109,MATCH(B47,'Employee Master'!$A$10:$A$109,0)),"") | E47: P | F47: 0.3875 | G47: 0.75347222 | H47: 0 | J47: =IF(AND(F47<>"",G47<>""),ROUND((G47-F47)*24,2),"") -> 8.78 | K47: =IF(F47<>"",IF(F47>Lists!$L$10,"Late","On Time"),"") -> On Time | L47: =IF(G47<>"",IF(G47<Lists!$L$11,"Early","On Time"),"") -> On Time | M47: =IF(E47="","",E47&IF(K47="Late"," +Late","")&IF(L47="Early"," +Early Exit","")) -> P
A48: 46252 | B48: XXX-39 | C48: =IFERROR(INDEX('Employee Master'!$B$10:$B$109,MATCH(B48,'Employee Master'!$A$10:$A$109,0)),"") | D48: =IFERROR(INDEX('Employee Master'!$H$10:$H$109,MATCH(B48,'Employee Master'!$A$10:$A$109,0)),"") | E48: P | F48: 0.38194444 | G48: 0.75 | H48: 0 | J48: =IF(AND(F48<>"",G48<>""),ROUND((G48-F48)*24,2),"") -> 8.83 | K48: =IF(F48<>"",IF(F48>Lists!$L$10,"Late","On Time"),"") -> On Time | L48: =IF(G48<>"",IF(G48<Lists!$L$11,"Early","On Time"),"") -> On Time | M48: =IF(E48="","",E48&IF(K48="Late"," +Late","")&IF(L48="Early"," +Early Exit","")) -> P
A49: 46252 | B49: XXX-40 | C49: =IFERROR(INDEX('Employee Master'!$B$10:$B$109,MATCH(B49,'Employee Master'!$A$10:$A$109,0)),"") | D49: =IFERROR(INDEX('Employee Master'!$H$10:$H$109,MATCH(B49,'Employee Master'!$A$10:$A$109,0)),"") | E49: P | F49: 0.39027778 | G49: 0.76388889 | H49: 0 | J49: =IF(AND(F49<>"",G49<>""),ROUND((G49-F49)*24,2),"") -> 8.97 | K49: =IF(F49<>"",IF(F49>Lists!$L$10,"Late","On Time"),"") -> On Time | L49: =IF(G49<>"",IF(G49<Lists!$L$11,"Early","On Time"),"") -> On Time | M49: =IF(E49="","",E49&IF(K49="Late"," +Late","")&IF(L49="Early"," +Early Exit","")) -> P
A50: 46252 | B50: XXX-41 | C50: =IFERROR(INDEX('Employee Master'!$B$10:$B$109,MATCH(B50,'Employee Master'!$A$10:$A$109,0)),"") | D50: =IFERROR(INDEX('Employee Master'!$H$10:$H$109,MATCH(B50,'Employee Master'!$A$10:$A$109,0)),"") | E50: P | F50: 0.38194444 | G50: 0.77430556 | H50: 0 | J50: =IF(AND(F50<>"",G50<>""),ROUND((G50-F50)*24,2),"") -> 9.42 | K50: =IF(F50<>"",IF(F50>Lists!$L$10,"Late","On Time"),"") -> On Time | L50: =IF(G50<>"",IF(G50<Lists!$L$11,"Early","On Time"),"") -> On Time | M50: =IF(E50="","",E50&IF(K50="Late"," +Late","")&IF(L50="Early"," +Early Exit","")) -> P
A51: 46252 | B51: XXX-42 | C51: =IFERROR(INDEX('Employee Master'!$B$10:$B$109,MATCH(B51,'Employee Master'!$A$10:$A$109,0)),"") | D51: =IFERROR(INDEX('Employee Master'!$H$10:$H$109,MATCH(B51,'Employee Master'!$A$10:$A$109,0)),"") | E51: P | F51: 0.37847222 | G51: 0.77430556 | H51: 0 | J51: =IF(AND(F51<>"",G51<>""),ROUND((G51-F51)*24,2),"") -> 9.5 | K51: =IF(F51<>"",IF(F51>Lists!$L$10,"Late","On Time"),"") -> On Time | L51: =IF(G51<>"",IF(G51<Lists!$L$11,"Early","On Time"),"") -> On Time | M51: =IF(E51="","",E51&IF(K51="Late"," +Late","")&IF(L51="Early"," +Early Exit","")) -> P
A52: 46252 | B52: XXX-43 | C52: =IFERROR(INDEX('Employee Master'!$B$10:$B$109,MATCH(B52,'Employee Master'!$A$10:$A$109,0)),"") | D52: =IFERROR(INDEX('Employee Master'!$H$10:$H$109,MATCH(B52,'Employee Master'!$A$10:$A$109,0)),"") | E52: P | F52: 0.39236111 | G52: 0.75347222 | H52: 1 | J52: =IF(AND(F52<>"",G52<>""),ROUND((G52-F52)*24,2),"") -> 8.67 | K52: =IF(F52<>"",IF(F52>Lists!$L$10,"Late","On Time"),"") -> On Time | L52: =IF(G52<>"",IF(G52<Lists!$L$11,"Early","On Time"),"") -> On Time | M52: =IF(E52="","",E52&IF(K52="Late"," +Late","")&IF(L52="Early"," +Early Exit","")) -> P
A53: 46252 | B53: XXX-44 | C53: =IFERROR(INDEX('Employee Master'!$B$10:$B$109,MATCH(B53,'Employee Master'!$A$10:$A$109,0)),"") | D53: =IFERROR(INDEX('Employee Master'!$H$10:$H$109,MATCH(B53,'Employee Master'!$A$10:$A$109,0)),"") | E53: P | F53: 0.42708333 | G53: 0.42013889 | H53: 0 | J53: =IF(AND(F53<>"",G53<>""),ROUND((G53-F53)*24,2),"") -> -0.17 | K53: =IF(F53<>"",IF(F53>Lists!$L$10,"Late","On Time"),"") -> Late | L53: =IF(G53<>"",IF(G53<Lists!$L$11,"Early","On Time"),"") -> Early | M53: =IF(E53="","",E53&IF(K53="Late"," +Late","")&IF(L53="Early"," +Early Exit","")) -> P +Late +Early Exit
... A56: 46252 | B56: XXX-47 | C56: =IFERROR(INDEX('Employee Master'!$B$10:$B$109,MATCH(B56,'Employee Master'!$A$10:$A$109,0)),"") | D56: =IFERROR(INDEX('Employee Master'!$H$10:$H$109,MATCH(B56,'Employee Master'!$A$10:$A$109,0)),"") | E56: P | F56: 0.39027778 | G56: 0.77430556 | H56: 3 | J56: =IF(AND(F56<>"",G56<>""),ROUND((G56-F56)*24,2),"") -> 9.22 | K56: =IF(F56<>"",IF(F56>Lists!$L$10,"Late","On Time"),"") -> On Time | L56: =IF(G56<>"",IF(G56<Lists!$L$11,"Early","On Time"),"") -> On Time | M56: =IF(E56="","",E56&IF(K56="Late"," +Late","")&IF(L56="Early"," +Early Exit","")) -> P
...

Sheet Leave Tracker
A1: LEAVE TRACKER
A2: Leave requests, approvals and day-count calculations linked to Employee Master
A3: HOME | B3: PEOPLE | C3: ATTEND. | D3: LEAVE | E3: PAYROLL | F3: DOCS | G3: COMPLY | H3: ANALYTICS | I3: MGMT
B5: TOTAL REQUESTS | D5: APPROVED | F5: PENDING | H5: REJECTED
B6: =COUNTA($A$10:$A$209) -> 18 | D6: =COUNTIF($H$10:$H$209,"Approved") -> 12 | F6: =COUNTIF($H$10:$H$209,"Pending") -> 4 | H6: =COUNTIF($H$10:$H$209,"Rejected") -> 2
A9: Leave ID | B9: Employee ID | C9: Employee Name | D9: From Date | E9: To Date | F9: Leave Type | G9: Days | H9: Approval Status | I9: Remarks
A10: LV-1000 | B10: XXX-01 | C10: =IFERROR(INDEX('Employee Master'!$B$10:$B$109,MATCH(B10,'Employee Master'!$A$10:$A$109,0)),"") -> Murugesan P | D10: 46250 | E10: 46251 | F10: ML | G10: =IF(OR(D10="",E10=""),"",E10-D10+1) -> 2 | H10: Pending
A11: LV-1001 | B11: XXX-02 | C11: =IFERROR(INDEX('Employee Master'!$B$10:$B$109,MATCH(B11,'Employee Master'!$A$10:$A$109,0)),"") -> Vijay K | D11: 46241 | E11: 46245 | F11: SL | G11: =IF(OR(D11="",E11=""),"",E11-D11+1) -> 5 | H11: Pending
A12: LV-1002 | B12: XXX-03 | C12: =IFERROR(INDEX('Employee Master'!$B$10:$B$109,MATCH(B12,'Employee Master'!$A$10:$A$109,0)),"") -> Murugesan P | D12: 46237 | E12: 46237 | F12: EL | G12: =IF(OR(D12="",E12=""),"",E12-D12+1) -> 1 | H12: Pending
A13: LV-1003 | B13: XXX-04 | C13: =IFERROR(INDEX('Employee Master'!$B$10:$B$109,MATCH(B13,'Employee Master'!$A$10:$A$109,0)),"") -> Murugesan S | D13: 46216 | E13: 46217 | F13: ML | G13: =IF(OR(D13="",E13=""),"",E13-D13+1) -> 2 | H13: Approved
A14: LV-1004 | B14: XXX-05 | C14: =IFERROR(INDEX('Employee Master'!$B$10:$B$109,MATCH(B14,'Employee Master'!$A$10:$A$109,0)),"") -> Murugesan | D14: 46229 | E14: 46229 | F14: EL | G14: =IF(OR(D14="",E14=""),"",E14-D14+1) -> 1 | H14: Approved
A15: LV-1005 | B15: XXX-06 | C15: =IFERROR(INDEX('Employee Master'!$B$10:$B$109,MATCH(B15,'Employee Master'!$A$10:$A$109,0)),"") -> Elango K | D15: 46244 | E15: 46245 | F15: EL | G15: =IF(OR(D15="",E15=""),"",E15-D15+1) -> 2 | H15: Pending
A16: LV-1006 | B16: XXX-07 | C16: =IFERROR(INDEX('Employee Master'!$B$10:$B$109,MATCH(B16,'Employee Master'!$A$10:$A$109,0)),"") -> Murugan | D16: 46228 | E16: 46230 | F16: LOP | G16: =IF(OR(D16="",E16=""),"",E16-D16+1) -> 3 | H16: Approved
A17: LV-1007 | B17: XXX-08 | C17: =IFERROR(INDEX('Employee Master'!$B$10:$B$109,MATCH(B17,'Employee Master'!$A$10:$A$109,0)),"") -> Bala Murugan | D17: 46217 | E17: 46218 | F17: SL | G17: =IF(OR(D17="",E17=""),"",E17-D17+1) -> 2 | H17: Approved
A18: LV-1008 | B18: XXX-09 | C18: =IFERROR(INDEX('Employee Master'!$B$10:$B$109,MATCH(B18,'Employee Master'!$A$10:$A$109,0)),"") -> Murugesan V | D18: 46235 | E18: 46235 | F18: CL | G18: =IF(OR(D18="",E18=""),"",E18-D18+1) -> 1 | H18: Rejected
A19: LV-1009 | B19: XXX-10 | C19: =IFERROR(INDEX('Employee Master'!$B$10:$B$109,MATCH(B19,'Employee Master'!$A$10:$A$109,0)),"") -> Elango P | D19: 46239 | E19: 46239 | F19: LOP | G19: =IF(OR(D19="",E19=""),"",E19-D19+1) -> 1 | H19: Approved
A20: LV-1010 | B20: XXX-11 | C20: =IFERROR(INDEX('Employee Master'!$B$10:$B$109,MATCH(B20,'Employee Master'!$A$10:$A$109,0)),"") -> Senthil Kumar K | D20: 46219 | E20: 46223 | F20: CL | G20: =IF(OR(D20="",E20=""),"",E20-D20+1) -> 5 | H20: Approved
A21: LV-1011 | B21: XXX-12 | C21: =IFERROR(INDEX('Employee Master'!$B$10:$B$109,MATCH(B21,'Employee Master'!$A$10:$A$109,0)),"") -> Saravanan P | D21: 46246 | E21: 46246 | F21: EL | G21: =IF(OR(D21="",E21=""),"",E21-D21+1) -> 1 | H21: Approved
... A27: LV-1017 | B27: XXX-18 | C27: =IFERROR(INDEX('Employee Master'!$B$10:$B$109,MATCH(B27,'Employee Master'!$A$10:$A$109,0)),"") -> Sowmya V | D27: 46228 | E27: 46228 | F27: LOP | G27: =IF(OR(D27="",E27=""),"",E27-D27+1) -> 1 | H27: Approved
B28: XXX-19 | C28: =IFERROR(INDEX('Employee Master'!$B$10:$B$109,MATCH(B28,'Employee Master'!$A$10:$A$109,0)),"") -> Nandhini | G28: =IF(OR(D28="",E28=""),"",E28-D28+1)
B29: XXX-20 | C29: =IFERROR(INDEX('Employee Master'!$B$10:$B$109,MATCH(B29,'Employee Master'!$A$10:$A$109,0)),"") -> Divya | G29: =IF(OR(D29="",E29=""),"",E29-D29+1)
B30: XXX-21 | C30: =IFERROR(INDEX('Employee Master'!$B$10:$B$109,MATCH(B30,'Employee Master'!$A$10:$A$109,0)),"") -> Divya K | G30: =IF(OR(D30="",E30=""),"",E30-D30+1)
B31: XXX-22 | C31: =IFERROR(INDEX('Employee Master'!$B$10:$B$109,MATCH(B31,'Employee Master'!$A$10:$A$109,0)),"") -> Karthik S | G31: =IF(OR(D31="",E31=""),"",E31-D31+1)
B32: XXX-23 | C32: =IFERROR(INDEX('Employee Master'!$B$10:$B$109,MATCH(B32,'Employee Master'!$A$10:$A$109,0)),"") -> Dinesh | G32: =IF(OR(D32="",E32=""),"",E32-D32+1)
B33: XXX-24 | C33: =IFERROR(INDEX('Employee Master'!$B$10:$B$109,MATCH(B33,'Employee Master'!$A$10:$A$109,0)),"") -> Kumaresan M | G33: =IF(OR(D33="",E33=""),"",E33-D33+1)
B34: XXX-25 | C34: =IFERROR(INDEX('Employee Master'!$B$10:$B$109,MATCH(B34,'Employee Master'!$A$10:$A$109,0)),"") -> Vijay P | G34: =IF(OR(D34="",E34=""),"",E34-D34+1)
B35: XXX-26 | C35: =IFERROR(INDEX('Employee Master'!$B$10:$B$109,MATCH(B35,'Employee Master'!$A$10:$A$109,0)),"") -> Divya R | G35: =IF(OR(D35="",E35=""),"",E35-D35+1)
B36: XXX-27 | C36: =IFERROR(INDEX('Employee Master'!$B$10:$B$109,MATCH(B36,'Employee Master'!$A$10:$A$109,0)),"") -> Selvam R | G36: =IF(OR(D36="",E36=""),"",E36-D36+1)
B37: XXX-28 | C37: =IFERROR(INDEX('Employee Master'!$B$10:$B$109,MATCH(B37,'Employee Master'!$A$10:$A$109,0)),"") -> Saravanan | G37: =IF(OR(D37="",E37=""),"",E37-D37+1)
B38: XXX-29 | C38: =IFERROR(INDEX('Employee Master'!$B$10:$B$109,MATCH(B38,'Employee Master'!$A$10:$A$109,0)),"") -> Nandhini R | G38: =IF(OR(D38="",E38=""),"",E38-D38+1)
B39: XXX-30 | C39: =IFERROR(INDEX('Employee Master'!$B$10:$B$109,MATCH(B39,'Employee Master'!$A$10:$A$109,0)),"") -> Kavitha R | G39: =IF(OR(D39="",E39=""),"",E39-D39+1)
... B45: XXX-36 | C45: =IFERROR(INDEX('Employee Master'!$B$10:$B$109,MATCH(B45,'Employee Master'!$A$10:$A$109,0)),"") -> Kavitha K | G45: =IF(OR(D45="",E45=""),"",E45-D45+1)
C46: =IFERROR(INDEX('Employee Master'!$B$10:$B$109,MATCH(B46,'Employee Master'!$A$10:$A$109,0)),"") | G46: =IF(OR(D46="",E46=""),"",E46-D46+1)
C47: =IFERROR(INDEX('Employee Master'!$B$10:$B$109,MATCH(B47,'Employee Master'!$A$10:$A$109,0)),"") | G47: =IF(OR(D47="",E47=""),"",E47-D47+1)
C48: =IFERROR(INDEX('Employee Master'!$B$10:$B$109,MATCH(B48,'Employee Master'!$A$10:$A$109,0)),"") | G48: =IF(OR(D48="",E48=""),"",E48-D48+1)
C49: =IFERROR(INDEX('Employee Master'!$B$10:$B$109,MATCH(B49,'Employee Master'!$A$10:$A$109,0)),"") | G49: =IF(OR(D49="",E49=""),"",E49-D49+1)
C50: =IFERROR(INDEX('Employee Master'!$B$10:$B$109,MATCH(B50,'Employee Master'!$A$10:$A$109,0)),"") | G50: =IF(OR(D50="",E50=""),"",E50-D50+1)
C51: =IFERROR(INDEX('Employee Master'!$B$10:$B$109,MATCH(B51,'Employee Master'!$A$10:$A$109,0)),"") | G51: =IF(OR(D51="",E51=""),"",E51-D51+1)
C52: =IFERROR(INDEX('Employee Master'!$B$10:$B$109,MATCH(B52,'Employee Master'!$A$10:$A$109,0)),"") | G52: =IF(OR(D52="",E52=""),"",E52-D52+1)
C53: =IFERROR(INDEX('Employee Master'!$B$10:$B$109,MATCH(B53,'Employee Master'!$A$10:$A$109,0)),"") | G53: =IF(OR(D53="",E53=""),"",E53-D53+1)
...

Sheet OT Tracker
A1: OVERTIME TRACKER
A2: Overtime hours, rates and approval status, feeding directly into Payroll
A3: HOME | B3: PEOPLE | C3: ATTEND. | D3: LEAVE | E3: PAYROLL | F3: DOCS | G3: COMPLY | H3: ANALYTICS | I3: MGMT
B5: TOTAL OT HOURS | D5: TOTAL OT AMOUNT | F5: EMPLOYEES WITH OT | H5: AVG OT HRS/ENTRY
B6: =SUM($E$10:$E$209) -> 108.5 | D6: =SUM($G$10:$G$209) -> 11280 | F6: =IFERROR(SUMPRODUCT((B10:B209<>"")/COUNTIF(B10:B209,B10:B209&"")),0) -> 45 | H6: =IFERROR(AVERAGE($E$10:$E$209),0) -> 2.4111111
A9: Date | B9: Employee ID | C9: Employee Name | D9: Department | E9: OT Hours | F9: OT Rate | G9: OT Amount | H9: Approval Status | I9: Remarks
A10: 46251 | B10: XXX-01 | C10: =IFERROR(INDEX('Employee Master'!$B$10:$B$109,MATCH(B10,'Employee Master'!$A$10:$A$109,0)),"") -> Murugesan P | D10: =IFERROR(INDEX('Employee Master'!$H$10:$H$109,MATCH(B10,'Employee Master'!$A$10:$A$109,0)),"") -> Human Resources | E10: 1.5 | F10: 120 | G10: =IFERROR(E10*F10,0) -> 180 | H10: Approved
A11: 46259 | B11: XXX-02 | C11: =IFERROR(INDEX('Employee Master'!$B$10:$B$109,MATCH(B11,'Employee Master'!$A$10:$A$109,0)),"") -> Vijay K | D11: =IFERROR(INDEX('Employee Master'!$H$10:$H$109,MATCH(B11,'Employee Master'!$A$10:$A$109,0)),"") -> Finance & Accounts | E11: 4 | F11: 120 | G11: =IFERROR(E11*F11,0) -> 480 | H11: Pending
A12: 46259 | B12: XXX-03 | C12: =IFERROR(INDEX('Employee Master'!$B$10:$B$109,MATCH(B12,'Employee Master'!$A$10:$A$109,0)),"") -> Murugesan P | D12: =IFERROR(INDEX('Employee Master'!$H$10:$H$109,MATCH(B12,'Employee Master'!$A$10:$A$109,0)),"") -> Administration | E12: 4 | F12: 120 | G12: =IFERROR(E12*F12,0) -> 480 | H12: Approved
A13: 46256 | B13: XXX-04 | C13: =IFERROR(INDEX('Employee Master'!$B$10:$B$109,MATCH(B13,'Employee Master'!$A$10:$A$109,0)),"") -> Murugesan S | D13: =IFERROR(INDEX('Employee Master'!$H$10:$H$109,MATCH(B13,'Employee Master'!$A$10:$A$109,0)),"") -> Operations | E13: 2.5 | F13: 120 | G13: =IFERROR(E13*F13,0) -> 300 | H13: Approved
A14: 46252 | B14: XXX-05 | C14: =IFERROR(INDEX('Employee Master'!$B$10:$B$109,MATCH(B14,'Employee Master'!$A$10:$A$109,0)),"") -> Murugesan | D14: =IFERROR(INDEX('Employee Master'!$H$10:$H$109,MATCH(B14,'Employee Master'!$A$10:$A$109,0)),"") -> Sales & Marketing | E14: 1.5 | F14: 120 | G14: =IFERROR(E14*F14,0) -> 180 | H14: Pending
A15: 46251 | B15: XXX-06 | C15: =IFERROR(INDEX('Employee Master'!$B$10:$B$109,MATCH(B15,'Employee Master'!$A$10:$A$109,0)),"") -> Elango K | D15: =IFERROR(INDEX('Employee Master'!$H$10:$H$109,MATCH(B15,'Employee Master'!$A$10:$A$109,0)),"") -> IT & Systems | E15: 1 | F15: 120 | G15: =IFERROR(E15*F15,0) -> 120 | H15: Pending
A16: 46251 | B16: XXX-07 | C16: =IFERROR(INDEX('Employee Master'!$B$10:$B$109,MATCH(B16,'Employee Master'!$A$10:$A$109,0)),"") -> Murugan | D16: =IFERROR(INDEX('Employee Master'!$H$10:$H$109,MATCH(B16,'Employee Master'!$A$10:$A$109,0)),"") -> Procurement | E16: 4 | F16: 120 | G16: =IFERROR(E16*F16,0) -> 480 | H16: Pending
A17: 46252 | B17: XXX-08 | C17: =IFERROR(INDEX('Employee Master'!$B$10:$B$109,MATCH(B17,'Employee Master'!$A$10:$A$109,0)),"") -> Bala Murugan | D17: =IFERROR(INDEX('Employee Master'!$H$10:$H$109,MATCH(B17,'Employee Master'!$A$10:$A$109,0)),"") -> Quality Control | E17: 3 | F17: 120 | G17: =IFERROR(E17*F17,0) -> 360 | H17: Approved
A18: 46259 | B18: XXX-09 | C18: =IFERROR(INDEX('Employee Master'!$B$10:$B$109,MATCH(B18,'Employee Master'!$A$10:$A$109,0)),"") -> Murugesan V | D18: =IFERROR(INDEX('Employee Master'!$H$10:$H$109,MATCH(B18,'Employee Master'!$A$10:$A$109,0)),"") -> Maintenance | E18: 1.5 | F18: 120 | G18: =IFERROR(E18*F18,0) -> 180 | H18: Approved
A19: 46258 | B19: XXX-10 | C19: =IFERROR(INDEX('Employee Master'!$B$10:$B$109,MATCH(B19,'Employee Master'!$A$10:$A$109,0)),"") -> Elango P | D19: =IFERROR(INDEX('Employee Master'!$H$10:$H$109,MATCH(B19,'Employee Master'!$A$10:$A$109,0)),"") -> Customer Support | E19: 4 | F19: 90 | G19: =IFERROR(E19*F19,0) -> 360 | H19: Approved
A20: 46252 | B20: XXX-11 | C20: =IFERROR(INDEX('Employee Master'!$B$10:$B$109,MATCH(B20,'Employee Master'!$A$10:$A$109,0)),"") -> Senthil Kumar K | D20: =IFERROR(INDEX('Employee Master'!$H$10:$H$109,MATCH(B20,'Employee Master'!$A$10:$A$109,0)),"") -> Human Resources | E20: 4 | F20: 90 | G20: =IFERROR(E20*F20,0) -> 360 | H20: Approved
A21: 46256 | B21: XXX-12 | C21: =IFERROR(INDEX('Employee Master'!$B$10:$B$109,MATCH(B21,'Employee Master'!$A$10:$A$109,0)),"") -> Saravanan P | D21: =IFERROR(INDEX('Employee Master'!$H$10:$H$109,MATCH(B21,'Employee Master'!$A$10:$A$109,0)),"") -> Finance & Accounts | E21: 2.5 | F21: 90 | G21: =IFERROR(E21*F21,0) -> 225 | H21: Pending
... A54: 46259 | B54: XXX-45 | C54: =IFERROR(INDEX('Employee Master'!$B$10:$B$109,MATCH(B54,'Employee Master'!$A$10:$A$109,0)),"") | D54: =IFERROR(INDEX('Employee Master'!$H$10:$H$109,MATCH(B54,'Employee Master'!$A$10:$A$109,0)),"") | E54: 1.5 | F54: 120 | G54: =IFERROR(E54*F54,0) -> 180 | H54: Approved
C55: =IFERROR(INDEX('Employee Master'!$B$10:$B$109,MATCH(B55,'Employee Master'!$A$10:$A$109,0)),"") | D55: =IFERROR(INDEX('Employee Master'!$H$10:$H$109,MATCH(B55,'Employee Master'!$A$10:$A$109,0)),"") | F55: 0 | G55: =IFERROR(E55*F55,0) -> 0
C56: =IFERROR(INDEX('Employee Master'!$B$10:$B$109,MATCH(B56,'Employee Master'!$A$10:$A$109,0)),"") | D56: =IFERROR(INDEX('Employee Master'!$H$10:$H$109,MATCH(B56,'Employee Master'!$A$10:$A$109,0)),"") | F56: 0 | G56: =IFERROR(E56*F56,0) -> 0
C57: =IFERROR(INDEX('Employee Master'!$B$10:$B$109,MATCH(B57,'Employee Master'!$A$10:$A$109,0)),"") | D57: =IFERROR(INDEX('Employee Master'!$H$10:$H$109,MATCH(B57,'Employee Master'!$A$10:$A$109,0)),"") | F57: 0 | G57: =IFERROR(E57*F57,0) -> 0
C58: =IFERROR(INDEX('Employee Master'!$B$10:$B$109,MATCH(B58,'Employee Master'!$A$10:$A$109,0)),"") | D58: =IFERROR(INDEX('Employee Master'!$H$10:$H$109,MATCH(B58,'Employee Master'!$A$10:$A$109,0)),"") | F58: 0 | G58: =IFERROR(E58*F58,0) -> 0
C59: =IFERROR(INDEX('Employee Master'!$B$10:$B$109,MATCH(B59,'Employee Master'!$A$10:$A$109,0)),"") | D59: =IFERROR(INDEX('Employee Master'!$H$10:$H$109,MATCH(B59,'Employee Master'!$A$10:$A$109,0)),"") | F59: 0 | G59: =IFERROR(E59*F59,0) -> 0
C60: =IFERROR(INDEX('Employee Master'!$B$10:$B$109,MATCH(B60,'Employee Master'!$A$10:$A$109,0)),"") | D60: =IFERROR(INDEX('Employee Master'!$H$10:$H$109,MATCH(B60,'Employee Master'!$A$10:$A$109,0)),"") | F60: 0 | G60: =IFERROR(E60*F60,0) -> 0
C61: =IFERROR(INDEX('Employee Master'!$B$10:$B$109,MATCH(B61,'Employee Master'!$A$10:$A$109,0)),"") | D61: =IFERROR(INDEX('Employee Master'!$H$10:$H$109,MATCH(B61,'Employee Master'!$A$10:$A$109,0)),"") | F61: 0 | G61: =IFERROR(E61*F61,0) -> 0
C62: =IFERROR(INDEX('Employee Master'!$B$10:$B$109,MATCH(B62,'Employee Master'!$A$10:$A$109,0)),"") | D62: =IFERROR(INDEX('Employee Master'!$H$10:$H$109,MATCH(B62,'Employee Master'!$A$10:$A$109,0)),"") | F62: 0 | G62: =IFERROR(E62*F62,0) -> 0
C63: =IFERROR(INDEX('Employee Master'!$B$10:$B$109,MATCH(B63,'Employee Master'!$A$10:$A$109,0)),"") | D63: =IFERROR(INDEX('Employee Master'!$H$10:$H$109,MATCH(B63,'Employee Master'!$A$10:$A$109,0)),"") | F63: 0 | G63: =IFERROR(E63*F63,0) -> 0
C64: =IFERROR(INDEX('Employee Master'!$B$10:$B$109,MATCH(B64,'Employee Master'!$A$10:$A$109,0)),"") | D64: =IFERROR(INDEX('Employee Master'!$H$10:$H$109,MATCH(B64,'Employee Master'!$A$10:$A$109,0)),"") | F64: 0 | G64: =IFERROR(E64*F64,0) -> 0
C65: =IFERROR(INDEX('Employee Master'!$B$10:$B$109,MATCH(B65,'Employee Master'!$A$10:$A$109,0)),"") | D65: =IFERROR(INDEX('Employee Master'!$H$10:$H$109,MATCH(B65,'Employee Master'!$A$10:$A$109,0)),"") | F65: 0 | G65: =IFERROR(E65*F65,0) -> 0
C66: =IFERROR(INDEX('Employee Master'!$B$10:$B$109,MATCH(B66,'Employee Master'!$A$10:$A$109,0)),"") | D66: =IFERROR(INDEX('Employee Master'!$H$10:$H$109,MATCH(B66,'Employee Master'!$A$10:$A$109,0)),"") | F66: 0 | G66: =IFERROR(E66*F66,0) -> 0
... C209: =IFERROR(INDEX('Employee Master'!$B$10:$B$109,MATCH(B209,'Employee Master'!$A$10:$A$109,0)),"") | D209: =IFERROR(INDEX('Employee Master'!$H$10:$H$109,MATCH(B209,'Employee Master'!$A$10:$A$109,0)),"") | F209: 0 | G209: =IFERROR(E209*F209,0) -> 0

Sheet Document Tracker
A1: EMPLOYEE DOCUMENT TRACKER
A2: Statutory & HR document completion status per employee
A3: HOME | B3: PEOPLE | C3: ATTEND. | D3: LEAVE | E3: PAYROLL | F3: DOCS | G3: COMPLY | H3: ANALYTICS | I3: MGMT
B5: AVG COMPLETION % | E5: FULLY COMPLETE | H5: EMPLOYEES W/ GAPS | K5: MISSING DOCUMENTS
B6: =IFERROR(AVERAGE($I$10:$I$109),0) -> 0.54444444 | E6: =COUNTIF($I$10:$I$109,1) -> 4 | H6: =COUNTIFS($I$10:$I$109,"<1",$A$10:$A$109,"<>") -> 41 | K6: =SUM($J$10:$J$109) -> 123
A9: Employee ID | B9: Employee Name | C9: PAN | D9: Aadhaar | E9: Bank Proof | F9: Education | G9: Appointment Letter | H9: Address Proof | I9: Completion % | J9: Missing Docs | K9: Remarks
A10: XXX-01 | B10: =IFERROR(INDEX('Employee Master'!$B$10:$B$109,MATCH(A10,'Employee Master'!$A$10:$A$109,0)),"") -> Murugesan P | C10: Available | D10: Available | E10: Available | F10: Available | G10: Expired | H10: Missing | I10: =IF(A10="","",COUNTIF(C10:H10,"Available")/6) -> 0.66666667 | J10: =IF(A10="",0,6-COUNTIF(C10:H10,"Available")) -> 2
A11: XXX-02 | B11: =IFERROR(INDEX('Employee Master'!$B$10:$B$109,MATCH(A11,'Employee Master'!$A$10:$A$109,0)),"") -> Vijay K | C11: Available | D11: Available | E11: Available | F11: Available | G11: Available | H11: Available | I11: =IF(A11="","",COUNTIF(C11:H11,"Available")/6) -> 1 | J11: =IF(A11="",0,6-COUNTIF(C11:H11,"Available")) -> 0
A12: XXX-03 | B12: =IFERROR(INDEX('Employee Master'!$B$10:$B$109,MATCH(A12,'Employee Master'!$A$10:$A$109,0)),"") -> Murugesan P | C12: Pending | D12: Missing | E12: Available | F12: Pending | G12: Available | H12: Available | I12: =IF(A12="","",COUNTIF(C12:H12,"Available")/6) -> 0.5 | J12: =IF(A12="",0,6-COUNTIF(C12:H12,"Available")) -> 3
A13: XXX-04 | B13: =IFERROR(INDEX('Employee Master'!$B$10:$B$109,MATCH(A13,'Employee Master'!$A$10:$A$109,0)),"") -> Murugesan S | C13: Pending | D13: Available | E13: Available | F13: Available | G13: Available | H13: Missing | I13: =IF(A13="","",COUNTIF(C13:H13,"Available")/6) -> 0.66666667 | J13: =IF(A13="",0,6-COUNTIF(C13:H13,"Available")) -> 2
A14: XXX-05 | B14: =IFERROR(INDEX('Employee Master'!$B$10:$B$109,MATCH(A14,'Employee Master'!$A$10:$A$109,0)),"") -> Murugesan | C14: Missing | D14: Available | E14: Available | F14: Available | G14: Missing | H14: Available | I14: =IF(A14="","",COUNTIF(C14:H14,"Available")/6) -> 0.66666667 | J14: =IF(A14="",0,6-COUNTIF(C14:H14,"Available")) -> 2
A15: XXX-06 | B15: =IFERROR(INDEX('Employee Master'!$B$10:$B$109,MATCH(A15,'Employee Master'!$A$10:$A$109,0)),"") -> Elango K | C15: Available | D15: Available | E15: Available | F15: Available | G15: Expired | H15: Pending | I15: =IF(A15="","",COUNTIF(C15:H15,"Available")/6) -> 0.66666667 | J15: =IF(A15="",0,6-COUNTIF(C15:H15,"Available")) -> 2
A16: XXX-07 | B16: =IFERROR(INDEX('Employee Master'!$B$10:$B$109,MATCH(A16,'Employee Master'!$A$10:$A$109,0)),"") -> Murugan | C16: Available | D16: Available | E16: Expired | F16: Pending | G16: Available | H16: Available | I16: =IF(A16="","",COUNTIF(C16:H16,"Available")/6) -> 0.66666667 | J16: =IF(A16="",0,6-COUNTIF(C16:H16,"Available")) -> 2
A17: XXX-08 | B17: =IFERROR(INDEX('Employee Master'!$B$10:$B$109,MATCH(A17,'Employee Master'!$A$10:$A$109,0)),"") -> Bala Murugan | C17: Expired | D17: Available | E17: Expired | F17: Available | G17: Pending | H17: Available | I17: =IF(A17="","",COUNTIF(C17:H17,"Available")/6) -> 0.5 | J17: =IF(A17="",0,6-COUNTIF(C17:H17,"Available")) -> 3
A18: XXX-09 | B18: =IFERROR(INDEX('Employee Master'!$B$10:$B$109,MATCH(A18,'Employee Master'!$A$10:$A$109,0)),"") -> Murugesan V | C18: Pending | D18: Available | E18: Available | F18: Pending | G18: Available | H18: Available | I18: =IF(A18="","",COUNTIF(C18:H18,"Available")/6) -> 0.66666667 | J18: =IF(A18="",0,6-COUNTIF(C18:H18,"Available")) -> 2
A19: XXX-10 | B19: =IFERROR(INDEX('Employee Master'!$B$10:$B$109,MATCH(A19,'Employee Master'!$A$10:$A$109,0)),"") -> Elango P | C19: Available | D19: Available | E19: Pending | F19: Available | G19: Missing | H19: Pending | I19: =IF(A19="","",COUNTIF(C19:H19,"Available")/6) -> 0.5 | J19: =IF(A19="",0,6-COUNTIF(C19:H19,"Available")) -> 3
A20: XXX-11 | B20: =IFERROR(INDEX('Employee Master'!$B$10:$B$109,MATCH(A20,'Employee Master'!$A$10:$A$109,0)),"") -> Senthil Kumar K | C20: Available | D20: Available | E20: Pending | F20: Available | G20: Expired | H20: Available | I20: =IF(A20="","",COUNTIF(C20:H20,"Available")/6) -> 0.66666667 | J20: =IF(A20="",0,6-COUNTIF(C20:H20,"Available")) -> 2
A21: XXX-12 | B21: =IFERROR(INDEX('Employee Master'!$B$10:$B$109,MATCH(A21,'Employee Master'!$A$10:$A$109,0)),"") -> Saravanan P | C21: Available | D21: Available | E21: Pending | F21: Available | G21: Available | H21: Available | I21: =IF(A21="","",COUNTIF(C21:H21,"Available")/6) -> 0.83333333 | J21: =IF(A21="",0,6-COUNTIF(C21:H21,"Available")) -> 1
... A45: XXX-36 | B45: =IFERROR(INDEX('Employee Master'!$B$10:$B$109,MATCH(A45,'Employee Master'!$A$10:$A$109,0)),"") -> Kavitha K | C45: Pending | D45: Expired | E45: Missing | F45: Available | G45: Available | H45: Available | I45: =IF(A45="","",COUNTIF(C45:H45,"Available")/6) -> 0.5 | J45: =IF(A45="",0,6-COUNTIF(C45:H45,"Available")) -> 3
A46: XXX-37 | B46: =IFERROR(INDEX('Employee Master'!$B$10:$B$109,MATCH(A46,'Employee Master'!$A$10:$A$109,0)),"") | I46: =IF(A46="","",COUNTIF(C46:H46,"Available")/6) -> 0 | J46: =IF(A46="",0,6-COUNTIF(C46:H46,"Available")) -> 6
A47: XXX-38 | B47: =IFERROR(INDEX('Employee Master'!$B$10:$B$109,MATCH(A47,'Employee Master'!$A$10:$A$109,0)),"") | I47: =IF(A47="","",COUNTIF(C47:H47,"Available")/6) -> 0 | J47: =IF(A47="",0,6-COUNTIF(C47:H47,"Available")) -> 6
A48: XXX-39 | B48: =IFERROR(INDEX('Employee Master'!$B$10:$B$109,MATCH(A48,'Employee Master'!$A$10:$A$109,0)),"") | I48: =IF(A48="","",COUNTIF(C48:H48,"Available")/6) -> 0 | J48: =IF(A48="",0,6-COUNTIF(C48:H48,"Available")) -> 6
A49: XXX-40 | B49: =IFERROR(INDEX('Employee Master'!$B$10:$B$109,MATCH(A49,'Employee Master'!$A$10:$A$109,0)),"") | I49: =IF(A49="","",COUNTIF(C49:H49,"Available")/6) -> 0 | J49: =IF(A49="",0,6-COUNTIF(C49:H49,"Available")) -> 6
A50: XXX-41 | B50: =IFERROR(INDEX('Employee Master'!$B$10:$B$109,MATCH(A50,'Employee Master'!$A$10:$A$109,0)),"") | I50: =IF(A50="","",COUNTIF(C50:H50,"Available")/6) -> 0 | J50: =IF(A50="",0,6-COUNTIF(C50:H50,"Available")) -> 6
A51: XXX-42 | B51: =IFERROR(INDEX('Employee Master'!$B$10:$B$109,MATCH(A51,'Employee Master'!$A$10:$A$109,0)),"") | I51: =IF(A51="","",COUNTIF(C51:H51,"Available")/6) -> 0 | J51: =IF(A51="",0,6-COUNTIF(C51:H51,"Available")) -> 6
A52: XXX-43 | B52: =IFERROR(INDEX('Employee Master'!$B$10:$B$109,MATCH(A52,'Employee Master'!$A$10:$A$109,0)),"") | I52: =IF(A52="","",COUNTIF(C52:H52,"Available")/6) -> 0 | J52: =IF(A52="",0,6-COUNTIF(C52:H52,"Available")) -> 6
A53: XXX-44 | B53: =IFERROR(INDEX('Employee Master'!$B$10:$B$109,MATCH(A53,'Employee Master'!$A$10:$A$109,0)),"") | I53: =IF(A53="","",COUNTIF(C53:H53,"Available")/6) -> 0 | J53: =IF(A53="",0,6-COUNTIF(C53:H53,"Available")) -> 6
